<robot name="p3020" xmlns:xacro="http://www.ros.org/wiki/xacro">
  <link name="base_link">
            <visual>
                <geometry>
                    <mesh scale="0.001 0.001 0.001" filename="package://dsr_description2/meshes/p3020/1.STL"/>
                </geometry>
            </visual>
            <collision>
                <geometry>
                    <mesh scale="0.001 0.001 0.001" filename="package://dsr_description2/meshes/p3020/1.STL"/>
                </geometry>
            </collision>
        </link>

        <!-- link_1 -->
        <link name="link_1">
            <visual>
                <origin xyz="0 0 -0.3943"/>
                <geometry>
                    <mesh filename="package://dsr_description2/meshes/p3020/2-1.STL" scale="0.001 0.001 0.001" />
                </geometry>
            </visual>
            <visual>
                <origin xyz="0 0 -0.3943"/>
                <geometry>
                    <mesh filename="package://dsr_description2/meshes/p3020/2-2.STL" scale="0.001 0.001 0.001" />
                </geometry>
            </visual>
            <visual>
                <origin xyz="0 0 -0.3943"/>
                <geometry>
                    <mesh filename="package://dsr_description2/meshes/p3020/2-3.STL" scale="0.001 0.001 0.001" />
                </geometry>
            </visual>
            <visual>
                <origin xyz="0 0 -0.3943"/>
                <geometry>
                    <mesh filename="package://dsr_description2/meshes/p3020/2-4.STL" scale="0.001 0.001 0.001" />
                </geometry>
            </visual>
            <visual>
                <origin xyz="0 0 -0.3943"/>
                <geometry>
                    <mesh filename="package://dsr_description2/meshes/p3020/2-5.STL" scale="0.001 0.001 0.001" />
                </geometry>
            </visual>

            <collision>
                <origin xyz="0 0 -0.3943"/>
                <geometry>
                    <mesh filename="package://dsr_description2/meshes/p3020/2-1.STL" scale="0.001 0.001 0.001" />
                </geometry>
            </collision>
            <collision>
                <origin xyz="0 0 -0.3943"/>
                <geometry>
                    <mesh filename="package://dsr_description2/meshes/p3020/2-2.STL" scale="0.001 0.001 0.001" />
                </geometry>
            </collision>
            <collision>
                <origin xyz="0 0 -0.3943"/>
                <geometry>
                    <mesh filename="package://dsr_description2/meshes/p3020/2-3.STL" scale="0.001 0.001 0.001" />
                </geometry>
            </collision>
            <collision>
                <origin xyz="0 0 -0.3943"/>
                <geometry>
                    <mesh filename="package://dsr_description2/meshes/p3020/2-4.STL" scale="0.001 0.001 0.001" />
                </geometry>
            </collision>
            <collision>
                <origin xyz="0 0 -0.3943"/>
                <geometry>
                    <mesh filename="package://dsr_description2/meshes/p3020/2-5.STL" scale="0.001 0.001 0.001" />
                </geometry>
            </collision>
        </link>

        <!-- link_2 -->
        <link name="link_2">
            <visual>
                <origin xyz="0 0 -0.3943"/>
                <geometry>
                    <mesh filename="package://dsr_description2/meshes/p3020/3-1.STL" scale="0.001 0.001 0.001" color="0 0 0 1"/>
                </geometry>
                
            </visual>
            <visual>
                <origin xyz="0 0 -0.3943"/>
                <geometry>
                    <mesh filename="package://dsr_description2/meshes/p3020/3-2.STL" scale="0.001 0.001 0.001" />
                </geometry>
            </visual>
            <visual>
                <origin xyz="0 0 -0.3943"/>
                <geometry>
                    <mesh filename="package://dsr_description2/meshes/p3020/3-3.STL" scale="0.001 0.001 0.001" />
                </geometry>
            </visual>
            <visual>
                <origin xyz="0 0 -0.3943"/>
                <geometry>
                    <mesh filename="package://dsr_description2/meshes/p3020/3-4.STL" scale="0.001 0.001 0.001" />
                </geometry>
            </visual>
            <visual>
                <origin xyz="0 0 -0.3943"/>
                <geometry>
                    <mesh filename="package://dsr_description2/meshes/p3020/3-5.STL" scale="0.001 0.001 0.001" />
                </geometry>
            </visual>
            <visual>
                <origin xyz="0 0 -0.3943"/>
                <geometry>
                    <mesh filename="package://dsr_description2/meshes/p3020/3-6.STL" scale="0.001 0.001 0.001" />
                </geometry>
            </visual>
            <visual>
                <origin xyz="0 0 -0.3943"/>
                <geometry>
                    <mesh filename="package://dsr_description2/meshes/p3020/3-7.STL" scale="0.001 0.001 0.001" />
                </geometry>
            </visual>
            <visual>
                <origin xyz="0 0 -0.3943"/>
                <geometry>
                    <mesh filename="package://dsr_description2/meshes/p3020/3-8.STL" scale="0.001 0.001 0.001" />
                </geometry>
                    <color rgba="0.490 0.490 0.486 1.0" />
            </visual>

            <collision>
                <origin xyz="0 0 -0.3943"/>
                <geometry>
                    <mesh filename="package://dsr_description2/meshes/p3020/3-1.STL" scale="0.001 0.001 0.001" />
                </geometry>
            </collision>
            <collision>
                <origin xyz="0 0 -0.3943"/>
                <geometry>
                    <mesh filename="package://dsr_description2/meshes/p3020/3-2.STL" scale="0.001 0.001 0.001" />
                </geometry>
            </collision>
            <collision>
                <origin xyz="0 0 -0.3943"/>
                <geometry>
                    <mesh filename="package://dsr_description2/meshes/p3020/3-3.STL" scale="0.001 0.001 0.001" />
                </geometry>
            </collision>
            <collision>
                <origin xyz="0 0 -0.3943"/>
                <geometry>
                    <mesh filename="package://dsr_description2/meshes/p3020/3-4.STL" scale="0.001 0.001 0.001" />
                </geometry>
            </collision>
            <collision>
                <origin xyz="0 0 -0.3943"/>
                <geometry>
                    <mesh filename="package://dsr_description2/meshes/p3020/3-5.STL" scale="0.001 0.001 0.001" />
                </geometry>
            </collision>
            <collision>
                <origin xyz="0 0 -0.3943"/>
                <geometry>
                    <mesh filename="package://dsr_description2/meshes/p3020/3-6.STL" scale="0.001 0.001 0.001" />
                </geometry>
            </collision>
            <collision>
                <origin xyz="0 0 -0.3943"/>
                <geometry>
                    <mesh filename="package://dsr_description2/meshes/p3020/3-7.STL" scale="0.001 0.001 0.001" />
                </geometry>
            </collision>
            <collision>
                <origin xyz="0 0 -0.3943"/>
                <geometry>
                    <mesh filename="package://dsr_description2/meshes/p3020/3-8.STL" scale="0.001 0.001 0.001" />
                </geometry>
            </collision>
        </link>

        <!-- link_3 -->
        <link name="link_3">
            <visual>
                <origin xyz="0 0 -1.4043"/>
                <geometry>
                    <mesh filename="package://dsr_description2/meshes/p3020/4-1.STL" scale="0.001 0.001 0.001" />
                </geometry>
            </visual>
            <visual>
                <origin xyz="0 0 -1.4043"/>
                <geometry>
                    <mesh filename="package://dsr_description2/meshes/p3020/4-2.STL" scale="0.001 0.001 0.001" />
                </geometry>
            </visual>
            <visual>
                <origin xyz="0 0 -1.4043"/>
                <geometry>
                    <mesh filename="package://dsr_description2/meshes/p3020/4-3.STL" scale="0.001 0.001 0.001" />
                </geometry>
            </visual>
            <visual>
                <origin xyz="0 0 -1.4043"/>
                <geometry>
                    <mesh filename="package://dsr_description2/meshes/p3020/4-4.STL" scale="0.001 0.001 0.001" />
                </geometry>
            </visual>
            <collision>
                <origin xyz="0 0 -1.4043"/>
                <geometry>
                    <mesh filename="package://dsr_description2/meshes/p3020/4-1.STL" scale="0.001 0.001 0.001" />
                </geometry>
            </collision>
            <collision>
                <origin xyz="0 0 -1.4043"/>
                <geometry>
                    <mesh filename="package://dsr_description2/meshes/p3020/4-2.STL" scale="0.001 0.001 0.001" />
                </geometry>
            </collision>
            <collision>
                <origin xyz="0 0 -1.4043"/>
                <geometry>
                    <mesh filename="package://dsr_description2/meshes/p3020/4-3.STL" scale="0.001 0.001 0.001" />
                </geometry>
            </collision>
            <collision>
                <origin xyz="0 0 -1.4043"/>
                <geometry>
                    <mesh filename="package://dsr_description2/meshes/p3020/4-4.STL" scale="0.001 0.001 0.001" />
                </geometry>
            </collision>
        </link>

        <!-- link_4 (Dummy Link for joint_4) -->
        <link name="link_4">

        </link>

        <!-- link_5 -->
        <link name="link_5">
            <visual>
                <origin xyz="0 -0.20785 -2.2943"/>
                <geometry>
                    <mesh filename="package://dsr_description2/meshes/p3020/6-1.STL" scale="0.001 0.001 0.001" />
                </geometry>
            </visual>
            <visual>
                <origin xyz="0 -0.20785 -2.2943"/>
                <geometry>
                    <mesh filename="package://dsr_description2/meshes/p3020/6-2.STL" scale="0.001 0.001 0.001" />
                </geometry>
            </visual>
            <visual>
                <origin xyz="0 -0.20785 -2.2943"/>
                <geometry>
                    <mesh filename="package://dsr_description2/meshes/p3020/6-3.STL" scale="0.001 0.001 0.001" />
                </geometry>
            </visual>
            <collision>
                <origin xyz="0 -0.20785 -2.2943"/>
                <geometry>
                    <mesh filename="package://dsr_description2/meshes/p3020/6-1.STL" scale="0.001 0.001 0.001" />
                </geometry>
            </collision>
            <collision>
                <origin xyz="0 -0.20785 -2.2943"/>
                <geometry>
                    <mesh filename="package://dsr_description2/meshes/p3020/6-2.STL" scale="0.001 0.001 0.001" />
                </geometry>
            </collision>
            <collision>
                <origin xyz="0 -0.20785 -2.2943"/>
                <geometry>
                    <mesh filename="package://dsr_description2/meshes/p3020/6-3.STL" scale="0.001 0.001 0.001" />
                </geometry>
            </collision>
        </link>

        <!-- link_6 -->
        <link name="link_6">
            <visual>
                <origin xyz="0 -0.20785 -2.4243"/>
                <geometry>
                    <mesh filename="package://dsr_description2/meshes/p3020/7.STL" scale="0.001 0.001 0.001" />
                </geometry>
            </visual>
            <collision>
                <geometry>
                    <mesh filename="package://dsr_description2/meshes/p3020/7.STL" scale="0.001 0.001 0.001" />
                </geometry>
            </collision>
        </link>

        <!-- Joints -->
        <joint name="joint_1" type="revolute">
            <origin xyz="0 0 0.3943"/>
			<limit effort="50" lower="-6.2832" upper="6.2832" velocity="3.927"/>
            <parent link="base_link"/>
            <child link="link_1"/>
            <axis xyz="0 0 1"/>
        </joint>

        <joint name="joint_2" type="revolute">
            <origin xyz="0 0 0"/>
			<limit effort="50" lower="-6.2832" upper="6.2832" velocity="3.927"/>
            <parent link="link_1"/>
            <child link="link_2"/>
            <axis xyz="0 1 0"/>
        </joint>

        <joint name="joint_3" type="revolute">
            <origin xyz="0 0 1.01"/>
			<limit effort="50" lower="-6.2832" upper="6.2832" velocity="3.927"/>
            <parent link="link_2"/>
            <child link="link_3"/>
            <axis xyz="0 1 0"/>
        </joint>

        <!-- Dummy joint_4 -->
        <joint name="joint_4" type="fixed">
            <origin xyz="0 0 0"/>  <!-- Fixed at the same position -->
			<!-- <limit effort="50" lower="-6.2832" upper="6.2832" velocity="3.927"/> -->
            <parent link="link_3"/>
            <child link="link_4"/>
        </joint>

        <joint name="joint_5" type="revolute">
            <origin xyz="0 0.20785 0.89"/>
			<limit effort="50" lower="-6.2832" upper="6.2832" velocity="3.927"/>
            <parent link="link_4"/>
            <child link="link_5"/>
            <axis xyz="0 1 0"/>
        </joint>

        <joint name="joint_6" type="revolute">
            <origin xyz="0 0 0.13"/>
			<limit effort="50" lower="-6.2832" upper="6.2832" velocity="3.927"/>
            <parent link="link_5"/>
            <child link="link_6"/>
            <axis xyz="0 0 1"/>
        </joint>
</robot>