<?xml version='1.0' encoding='utf-8'?>
<mujoco model="m1013">

  <asset>
    <mesh name="MF1013_0_0" file="MF1013_0_0.stl" scale="0.001 0.001 0.001" />
    <mesh name="MF1013_1_0" file="MF1013_1_0.stl" scale="0.001 0.001 0.001" />
    <mesh name="MF1013_2_0" file="MF1013_2_0.stl" scale="0.001 0.001 0.001" />
    <mesh name="MF1013_2_1" file="MF1013_2_1.stl" scale="0.001 0.001 0.001" />
    <mesh name="MF1013_2_2" file="MF1013_2_2.stl" scale="0.001 0.001 0.001" />
    <mesh name="MF1013_3_0" file="MF1013_3_0.stl" scale="0.001 0.001 0.001" />
    <mesh name="MF1013_4_0" file="MF1013_4_0.stl" scale="0.001 0.001 0.001" />
    <mesh name="MF1013_4_1" file="MF1013_4_1.stl" scale="0.001 0.001 0.001" />
    <mesh name="MF1013_5_0" file="MF1013_5_0.stl" scale="0.001 0.001 0.001" />
    <mesh name="MF1013_6_0" file="MF1013_6_0.stl" scale="0.001 0.001 0.001" />
  <material name="metal" rgba="0.58 0.58 0.58 1" />
    <material name="silicone" rgba="0.1882 0.1882 0.1882 1" />
    <material name="gray" rgba="0.4627 0.4627 0.4627 1" />
    <material name="black" rgba="0.149 0.149 0.149 1" />
    <mesh class="2f85" file="../../2f85/base_mount.stl" />
    <mesh class="2f85" file="../../2f85/base.stl" />
    <mesh class="2f85" file="../../2f85/driver.stl" />
    <mesh class="2f85" file="../../2f85/coupler.stl" />
    <mesh class="2f85" file="../../2f85/follower.stl" />
    <mesh class="2f85" file="../../2f85/pad.stl" />
    <mesh class="2f85" file="../../2f85/silicone_pad.stl" />
    <mesh class="2f85" file="../../2f85/spring_link.stl" />
  </asset>

  <worldbody>
    <geom type="mesh" mesh="MF1013_0_0" />
    <geom type="mesh" contype="0" conaffinity="0" group="1" density="0" mesh="MF1013_0_0" />
    <body name="link_1" pos="0 0 0.1525">
      <inertial pos="0.000119 0.0428 -0.006383" quat="0.464342 0.521165 -0.533586 0.477557" mass="7.8" diaginertia="0.0472838 0.0450586 0.0294526" />
      <joint name="joint_1" pos="0 0 0" axis="0 0 1" range="-6.2832 6.2832" actuatorfrcrange="-300 300" damping="400" frictionloss="1" />
      <geom type="mesh" mesh="MF1013_1_0" />
      <geom type="mesh" contype="0" conaffinity="0" group="1" density="0" mesh="MF1013_1_0" />
      <body name="link_2" pos="0 0.0345 0" quat="0.499898 -0.500102 -0.5 -0.5">
        <inertial pos="0.25973 -5.3e-05 0.15782" quat="0.0181111 0.703821 0.0182764 0.709911" mass="10.83" diaginertia="0.850272 0.849428 0.0375257" />
        <joint name="joint_2" pos="0 0 0" axis="0 0 1" range="-6.2832 6.2832" actuatorfrcrange="-300 300" damping="400" frictionloss="1" />
        <geom type="mesh" mesh="MF1013_2_0" />
        <geom type="mesh" contype="0" conaffinity="0" group="1" density="0" mesh="MF1013_2_0" />
        <geom type="mesh" mesh="MF1013_2_1" />
        <geom type="mesh" contype="0" conaffinity="0" group="1" density="0" mesh="MF1013_2_1" />
        <geom type="mesh" mesh="MF1013_2_2" />
        <geom type="mesh" contype="0" conaffinity="0" group="1" density="0" mesh="MF1013_2_2" />
        <body name="link_3" pos="0.62 0 0" quat="0.707035 0 0 0.707179">
          <inertial pos="-1.5e-05 -0.006702 0.044608" quat="0.713939 -0.0462748 0.0455669 0.69719" mass="3.68" diaginertia="0.0191021 0.0187478 0.0113721" />
          <joint name="joint_3" pos="0 0 0" axis="0 0 1" range="-2.7925 2.7925" actuatorfrcrange="-300 300" damping="400" frictionloss="1" />
          <geom type="mesh" mesh="MF1013_3_0" />
          <geom type="mesh" contype="0" conaffinity="0" group="1" density="0" mesh="MF1013_3_0" />
          <body name="link_4" pos="0 -0.559 0" quat="0.707035 0.707179 0 0">
            <inertial pos="7.1e-05 0.091879 -0.18252" quat="0.987197 -0.159369 -0.000923443 -0.0064664" mass="3.82" diaginertia="0.19063 0.190249 0.0128173" />
            <joint name="joint_4" pos="0 0 0" axis="0 0 1" range="-6.2832 6.2832" actuatorfrcrange="-200 200" damping="400" frictionloss="1" />
            <geom type="mesh" mesh="MF1013_4_0" />
            <geom type="mesh" contype="0" conaffinity="0" group="1" density="0" mesh="MF1013_4_0" />
            <geom type="mesh" mesh="MF1013_4_1" />
            <geom type="mesh" contype="0" conaffinity="0" group="1" density="0" mesh="MF1013_4_1" />
            <body name="link_5" quat="0.707035 -0.707179 0 0">
              <inertial pos="-0.000273 0.003651 0.032088" quat="0.996984 0.0775632 0.000422658 0.00257843" mass="2.82" diaginertia="0.0155831 0.0115855 0.00880048" />
              <joint name="joint_5" pos="0 0 0" axis="0 0 1" range="-6.2832 6.2832" actuatorfrcrange="-200 200" damping="400" frictionloss="1" />
              <geom type="mesh" mesh="MF1013_5_0" />
              <geom type="mesh" contype="0" conaffinity="0" group="1" density="0" mesh="MF1013_5_0" />
              <body name="link_6" pos="0 -0.121 0" quat="0.707035 0.707179 0 0">
                <inertial pos="-0.000292 7e-06 -0.0539" quat="0.0099287 0.708965 0.0073912 0.705135" mass="1.16" diaginertia="0.00612644 0.00595181 0.00482815" />
                <joint name="joint_6" pos="0 0 0" axis="0 0 1" range="-6.2832 6.2832" actuatorfrcrange="-50 50" damping="200" frictionloss="1" />
                <geom type="mesh" mesh="MF1013_6_0" />
                <geom type="mesh" contype="0" conaffinity="0" group="1" density="0" mesh="MF1013_6_0" />
              <body name="base_mount" pos="0 0 0.0075" childclass="2f85">
    <geom class="visual" mesh="base_mount" material="black" />
    <geom class="collision" mesh="base_mount" />
    <body name="base" pos="0 0 0.0038" quat="1 0 0 -1">
    <inertial mass="0.777441" pos="0 -2.70394e-05 0.0354675" quat="1 -0.00152849 0 0" diaginertia="0.000260285 0.000225381 0.000152708" />
    <geom class="visual" mesh="base" material="black" />
    <geom class="collision" mesh="base" />
    <site name="pinch" pos="0 0 0.145" type="sphere" group="5" rgba="0.9 0.9 0.9 1" size="0.005" />
    
    <body name="right_driver" pos="0 0.0306011 0.054904">
        <inertial mass="0.00899563" pos="2.96931e-12 0.0177547 0.00107314" quat="0.681301 0.732003 0 0" diaginertia="1.72352e-06 1.60906e-06 3.22006e-07" />
        <joint name="right_driver_joint" class="driver" />
        <geom class="visual" mesh="driver" material="gray" />
        <geom class="collision" mesh="driver" />
        <body name="right_coupler" pos="0 0.0315 -0.0041">
        <inertial mass="0.0140974" pos="0 0.00301209 0.0232175" quat="0.705636 -0.0455904 0.0455904 0.705636" diaginertia="4.16206e-06 3.52216e-06 8.88131e-07" />
        <joint name="right_coupler_joint" class="coupler" />
        <geom class="visual" mesh="coupler" material="black" />
        <geom class="collision" mesh="coupler" />
        </body>
    </body>
    <body name="right_spring_link" pos="0 0.0132 0.0609">
        <inertial mass="0.0221642" pos="-8.65005e-09 0.0181624 0.0212658" quat="0.663403 -0.244737 0.244737 0.663403" diaginertia="8.96853e-06 6.71733e-06 2.63931e-06" />
        <joint name="right_spring_link_joint" class="spring_link" />
        <geom class="visual" mesh="spring_link" material="black" />
        <geom class="collision" mesh="spring_link" />
        <body name="right_follower" pos="0 0.055 0.0375">
        <inertial mass="0.0125222" pos="0 -0.011046 0.0124786" quat="1 0.1664 0 0" diaginertia="2.67415e-06 2.4559e-06 6.02031e-07" />
        <joint name="right_follower_joint" class="follower" />
        <geom class="visual" mesh="follower" material="black" />
        <geom class="collision" mesh="follower" />
        <body name="right_pad" pos="0 -0.0189 0.01352">
            <geom class="pad_box1" name="right_pad1" />
            <geom class="pad_box2" name="right_pad2" />
            <inertial mass="0.0035" pos="0 -0.0025 0.0185" quat="0.707107 0 0 0.707107" diaginertia="4.73958e-07 3.64583e-07 1.23958e-07" />
            <geom class="visual" mesh="pad" />
            <body name="right_silicone_pad">
            <geom class="visual" mesh="silicone_pad" material="black" />
            </body>
        </body>
        </body>
    </body>
    
    <body name="left_driver" pos="0 -0.0306011 0.054904" quat="0 0 0 1">
        <inertial mass="0.00899563" pos="0 0.0177547 0.00107314" quat="0.681301 0.732003 0 0" diaginertia="1.72352e-06 1.60906e-06 3.22006e-07" />
        <joint name="left_driver_joint" class="driver" />
        <geom class="visual" mesh="driver" material="gray" />
        <geom class="collision" mesh="driver" />
        <body name="left_coupler" pos="0 0.0315 -0.0041">
        <inertial mass="0.0140974" pos="0 0.00301209 0.0232175" quat="0.705636 -0.0455904 0.0455904 0.705636" diaginertia="4.16206e-06 3.52216e-06 8.88131e-07" />
        <joint name="left_coupler_joint" class="coupler" />
        <geom class="visual" mesh="coupler" material="black" />
        <geom class="collision" mesh="coupler" />
        </body>
    </body>
    <body name="left_spring_link" pos="0 -0.0132 0.0609" quat="0 0 0 1">
        <inertial mass="0.0221642" pos="-8.65005e-09 0.0181624 0.0212658" quat="0.663403 -0.244737 0.244737 0.663403" diaginertia="8.96853e-06 6.71733e-06 2.63931e-06" />
        <joint name="left_spring_link_joint" class="spring_link" />
        <geom class="visual" mesh="spring_link" material="black" />
        <geom class="collision" mesh="spring_link" />
        <body name="left_follower" pos="0 0.055 0.0375">
        <inertial mass="0.0125222" pos="0 -0.011046 0.0124786" quat="1 0.1664 0 0" diaginertia="2.67415e-06 2.4559e-06 6.02031e-07" />
        <joint name="left_follower_joint" class="follower" />
        <geom class="visual" mesh="follower" material="black" />
        <geom class="collision" mesh="follower" />
        <body name="left_pad" pos="0 -0.0189 0.01352">
            <geom class="pad_box1" name="left_pad1" />
            <geom class="pad_box2" name="left_pad2" />
            <inertial mass="0.0035" pos="0 -0.0025 0.0185" quat="1 0 0 1" diaginertia="4.73958e-07 3.64583e-07 1.23958e-07" />
            <geom class="visual" mesh="pad" />
            <body name="left_silicone_pad">
            <geom class="visual" mesh="silicone_pad" material="black" />
            </body>
        </body>
        </body>
    </body>
    </body>
</body>


  
  </body>
            </body>
          </body>
        </body>
      </body>
    </body>
  </worldbody>
<default><default class="2f85">
      <mesh scale="0.001 0.001 0.001" />
      <general biastype="affine" />

      <joint axis="1 0 0" />
      <default class="driver">
        
        <joint range="0 0.8" armature="0.005" damping="30" solimplimit="0.95 0.99 0.001" solreflimit="0.005 1" />
      </default>
      <default class="follower">
        <joint range="-0.872664 0.872664" armature="0.001" pos="0 -0.018 0.0065" solimplimit="0.95 0.99 0.001" solreflimit="0.005 1" />
      </default>
      <default class="spring_link">
        
        <joint range="-0.29670597283 0.8" armature="0.001" stiffness="0.15" springref="2.62" damping="0.10125" />
      </default>
      <default class="coupler">
        <joint range="-1.57 0" armature="0.001" solimplimit="0.95 0.99 0.001" solreflimit="0.005 1" />
      </default>

      <default class="visual">
        <geom type="mesh" contype="0" conaffinity="0" group="2" />
      </default>
      <default class="collision">
        <geom type="mesh" group="3" />
        <default class="pad_box1">
          <geom mass="0" type="box" pos="0 -0.0026 0.028125" size="0.011 0.004 0.009375" friction="0.7" solimp="0.95 0.99 0.001" solref="0.004 1" priority="1" rgba="0.55 0.55 0.55 1" />
        </default>
        <default class="pad_box2">
          <geom mass="0" type="box" pos="0 -0.0026 0.009375" size="0.011 0.004 0.009375" friction="0.6" solimp="0.95 0.99 0.001" solref="0.004 1" priority="1" rgba="0.45 0.45 0.45 1" />
        </default>
      </default>
    </default>
  </default><actuator><general class="2f85" name="fingers_actuator" tendon="split" forcerange="-5 5" ctrlrange="0 255" gainprm="0.3137255 0 0" biasprm="0 -100 -10" />

    

    <position joint="joint_1" kp="6000" kv="400" ctrlrange="-2.617 2.617" />
    <position joint="joint_2" kp="6000" kv="500" ctrlrange="-1.57 1.57" />
    <position joint="joint_3" kp="8000" kv="500" ctrlrange="-2.617 2.617" />
    <position joint="joint_4" kp="7000" kv="500" ctrlrange="-2.617 2.617" />
    <position joint="joint_5" kp="7000" kv="500" ctrlrange="-2.617 2.617" />
    <position joint="joint_6" kp="12000" kv="400" ctrlrange="-2.617 2.617" />
  </actuator><tendon><fixed name="split">
      <joint joint="right_driver_joint" coef="0.5" />
      <joint joint="left_driver_joint" coef="0.5" />
    </fixed>
  </tendon><sensor /><equality><connect anchor="0 0 0" body1="right_follower" body2="right_coupler" solimp="0.95 0.99 0.001" solref="0.005 1" />
    <connect anchor="0 0 0" body1="left_follower" body2="left_coupler" solimp="0.95 0.99 0.001" solref="0.005 1" />
    <joint joint1="right_driver_joint" joint2="left_driver_joint" polycoef="0 1 0 0 0" solimp="0.95 0.99 0.001" solref="0.005 1" />
  </equality><contact><exclude body1="base" body2="left_driver" />
    <exclude body1="base" body2="right_driver" />
    <exclude body1="base" body2="left_spring_link" />
    <exclude body1="base" body2="right_spring_link" />
    <exclude body1="right_coupler" body2="right_follower" />
    <exclude body1="left_coupler" body2="left_follower" />
  </contact></mujoco>