<?xml version="1.0" ?>
<!-- =================================================================================== -->
<!-- |    This document was autogenerated by xacro from /home/theochoi/ros2_ws/src/doosan-robot2-Theo/dsr_description2/xacro/p3020.urdf.xacro | -->
<!-- |    EDITING THIS FILE BY HAND IS NOT RECOMMENDED                                 | -->
<!-- =================================================================================== -->
<robot name="p3020">

  <mujoco>
        <compiler 
        meshdir="assets" 
        balanceinertia="true" 
        discardvisual="false" />
  </mujoco>

  
  <material name="black">
    <color rgba="0.0 0.0 0.0 1.0"/>
  </material>
  <material name="white">
    <color rgba="1.0 1.0 1.0 1.0"/>
  </material>
  <material name="orange">
    <color rgba="1.0 0.4 0.0 1.0"/>
  </material>
  <material name="dr_gray">
    <color rgba="0.490 0.490 0.486 1.0"/>
  </material>
  <material name="dr_white">
    <color rgba="0.941 0.941 0.941 1.0"/>
  </material>
  <material name="dr_blue">
    <color rgba="0 0 0.15 1"/>
  </material>
  <!-- Base Link -->
  <link name="base_link">
    <inertial>
      <mass value="9.55"/>
      <origin xyz="6e-06   -0.007232     0.10749"/>
      <inertia ixx="0.11196" ixy="1.4011e-05" ixz="-0.0049962" iyy="0.0065009" iyz="-0.004993" izz="0.0056525"/>
    </inertial>
    <visual>
      <origin rpy="0 0 0" xyz="0 0 0"/>
      <geometry>
        <mesh filename="P3020_0_1.STL" scale="0.001 0.001 0.001"/>
      </geometry>
      <material name="dr_white"/>
    </visual>
  </link>
  <!-- link_1 -->
  <link name="link_1">
    <inertial>
      <mass value="28.624"/>
      <origin xyz="-1.1e-05     0.11205   -0.065579"/>
      <inertia ixx="0.69287" ixy="4.9232e-05" ixz="-0.21299" iyy="0.36715" iyz="-0.00012952" izz="0.46086"/>
    </inertial>
    <visual>
      <origin xyz="0 0 -0.3943"/>
      <geometry>
        <mesh filename="P3020_1_1.STL" scale="0.001 0.001 0.001"/>
      </geometry>
      <material name="dr_blue"/>
    </visual>
    <visual>
      <origin xyz="0 0 -0.3943"/>
      <geometry>
        <mesh filename="P3020_1_2.STL" scale="0.001 0.001 0.001"/>
      </geometry>
      <material name="dr_blue"/>
    </visual>
    <visual>
      <origin xyz="0 0 -0.3943"/>
      <geometry>
        <mesh filename="P3020_1_3.STL" scale="0.001 0.001 0.001"/>
      </geometry>
      <material name="dr_blue"/>
    </visual>
    <visual>
      <origin xyz="0 0 -0.3943"/>
      <geometry>
        <mesh filename="P3020_1_4.STL" scale="0.001 0.001 0.001"/>
      </geometry>
      <material name="dr_blue"/>
    </visual>
    <visual>
      <origin xyz="0 0 -0.3943"/>
      <geometry>
        <mesh filename="P3020_1_5.STL" scale="0.001 0.001 0.001"/>
      </geometry>
      <material name="dr_blue"/>
    </visual>
  </link>
  <!-- link_2 -->
  <link name="link_2">
    <inertial>
      <mass value="30.357"/>
      <origin xyz="0.4005       5e-06    0.006736"/>
      <inertia ixx="0.17985" ixy="0.214" ixz="0.00018611" iyy="4.5411" iyz="-7.1656e-05" izz="4.4825"/>
    </inertial>
    <visual>
      <!-- <origin xyz="0 -0.2351 -0.3943" rpy="0  -1.5708 -1.-0.3943708"/> -->
      <origin rpy="1.5708 0 1.5708" xyz="-0.3943 0 -0.2351"/>
      <geometry>
        <mesh filename="P3020_2_1.STL" scale="0.001 0.001 0.001"/>
      </geometry>
      <material name="dr_blue"/>
    </visual>
    <visual>
      <!-- <origin xyz="0 -0.2351 -0.3943" rpy="-1.5708  -1.5708 -1.5708"/> -->
      <origin rpy="1.5708 0 1.5708" xyz="-0.3943 0 -0.2351"/>
      <geometry>
        <mesh filename="P3020_2_2.STL" scale="0.001 0.001 0.001"/>
      </geometry>
      <material name="dr_blue"/>
    </visual>
    <visual>
      <!-- <origin xyz="0 -0.2351 -0.3943" rpy="-1.5708  0 1.5708"/> -->
      <origin rpy="1.5708 0 1.5708" xyz="-0.3943 0 -0.2351"/>
      <geometry>
        <mesh filename="P3020_2_3.STL" scale="0.001 0.001 0.001"/>
      </geometry>
      <material name="dr_blue"/>
    </visual>
    <visual>
      <!-- <origin xyz="0 -0.2351 -0.3943" rpy="-1.5708  0 1.5708"/> -->
      <origin rpy="1.5708 0 1.5708" xyz="-0.3943 0 -0.2351"/>
      <geometry>
        <mesh filename="P3020_2_4.STL" scale="0.001 0.001 0.001"/>
      </geometry>
      <material name="dr_blue"/>
    </visual>
    <visual>
      <!-- <origin xyz="0 -0.2351 -0.3943" rpy="-1.5708  0 1.5708"/> -->
      <origin rpy="1.5708 0 1.5708" xyz="-0.3943 0 -0.2351"/>
      <geometry>
        <mesh filename="P3020_2_5.STL" scale="0.001 0.001 0.001"/>
      </geometry>
      <material name="dr_blue"/>
    </visual>
    <visual>
      <!-- <origin xyz="0 -0.2351 -0.3943" rpy="-1.5708  0 1.5708"/> -->
      <origin rpy="1.5708 0 1.5708" xyz="-0.3943 0 -0.2351"/>
      <geometry>
        <mesh filename="P3020_2_6.STL" scale="0.001 0.001 0.001"/>
      </geometry>
      <material name="dr_blue"/>
    </visual>
    <visual>
      <!-- <origin xyz="0 -0.2351 -0.3943" rpy="-1.5708  0 1.5708"/> -->
      <origin rpy="1.5708 0 1.5708" xyz="-0.3943 0 -0.2351"/>
      <geometry>
        <mesh filename="P3020_2_7.STL" scale="0.001 0.001 0.001"/>
      </geometry>
      <material name="dr_blue"/>
    </visual>
    <visual>
      <!-- <origin xyz="0 -0.2351 -0.3943" rpy="-1.5708  0 1.5708"/> -->
      <origin rpy="1.5708 0 1.5708" xyz="-0.3943 0 -0.2351"/>
      <geometry>
        <mesh filename="P3020_2_8.STL" scale="0.001 0.001 0.001"/>
      </geometry>
      <material name="dr_blue"/>
    </visual>
  </link>
  <!-- link_3 -->
  <link name="link_3">
    <inertial>
      <mass value="2.836"/>
      <origin xyz="1.8e-05   -0.010564    -0.12656"/>
      <inertia ixx="0.01971" ixy="-0.00099331" ixz="4.2183e-06" iyy="0.017956" iyz="3.5784e-06" izz="0.017026"/>
    </inertial>
    <visual>
      <origin rpy="1.5708 0 0" xyz="0 1.4043 -0.2351"/>
      <geometry>
        <mesh filename="P3020_3_1.STL" scale="0.001 0.001 0.001"/>
      </geometry>
      <material name="dr_blue"/>
    </visual>
    <visual>
      <origin rpy="1.5708 0 0" xyz="0 1.4043 -0.2351"/>
      <geometry>
        <mesh filename="P3020_3_2.STL" scale="0.001 0.001 0.001"/>
      </geometry>
      <material name="dr_blue"/>
    </visual>
    <visual>
      <origin rpy="1.5708 0 0" xyz="0 1.4043 -0.2351"/>
      <geometry>
        <mesh filename="P3020_3_3.STL" scale="0.001 0.001 0.001"/>
      </geometry>
      <material name="dr_blue"/>
    </visual>
    <visual>
      <origin rpy="1.5708 0 0" xyz="0 1.4043 -0.2351"/>
      <geometry>
        <mesh filename="P3020_3_4.STL" scale="0.001 0.001 0.001"/>
      </geometry>
      <material name="dr_blue"/>
    </visual>
  </link>
  <!-- link_4 (Dummy Link for joint_4) -->
  <link name="link_4">
    <inertial>
      <mass value="6.057"/>
      <origin xyz="-2.2e-05    -0.12656    -0.30746"/>
      <inertia ixx="0.56389" ixy="5.1281e-06" ixz="-0.00030672" iyy="0.56341" iyz="3.2061e-05" izz="0.023517"/>
    </inertial>
  </link>
  <!-- link_5 -->
  <link name="link_5">
    <inertial>
      <mass value="2.959"/>
      <origin xyz="2.9e-05    -0.00224   -0.050131"/>
      <inertia ixx="0.016572" ixy="6.5264e-05" ixz="7.6867e-06" iyy="0.013688" iyz="2.1143e-06" izz="0.0099949"/>
    </inertial>
    <visual>
      <origin rpy="1.5708 0 0" xyz="0 2.2943 -0.2079"/>
      <geometry>
        <mesh filename="P3020_5_1.STL" scale="0.001 0.001 0.001"/>
      </geometry>
      <material name="dr_blue"/>
    </visual>
    <visual>
      <origin rpy="1.5708 0 0" xyz="0 2.2943 -0.2079"/>
      <geometry>
        <mesh filename="P3020_5_2.STL" scale="0.001 0.001 0.001"/>
      </geometry>
      <material name="dr_blue"/>
    </visual>
    <visual>
      <origin rpy="1.5708 0 0" xyz="0 2.2943 -0.2079"/>
      <geometry>
        <mesh filename="P3020_5_3.STL" scale="0.001 0.001 0.001"/>
      </geometry>
      <material name="dr_blue"/>
    </visual>
  </link>
  <!-- link_6 -->
  <link name="link_6">
    <inertial>
      <mass value="1.087"/>
      <origin xyz="-0.000232   -0.027102   -0.055618"/>
      <inertia ixx="0.007557" ixy="6.9478e-06" ixz="-1.1434e-06" iyy="0.0071074" iyz="5.748e-06" izz="0.0078136"/>
    </inertial>
    <visual>
      <origin rpy="0 0 0" xyz="0 -0.2079 -2.4243"/>
      <geometry>
        <mesh filename="P3020_6_1.STL" scale="0.001 0.001 0.001"/>
      </geometry>
      <material name="dr_white"/>
    </visual>
  </link>
  <!-- Joints -->
  <joint name="joint_1" type="revolute">
    <parent link="base_link"/>
    <child link="link_1"/>
    <origin rpy="0  0  0" xyz="0           0      0.3943"/>
    <axis xyz="0 0 1"/>
    <limit effort="459" lower="-6.2832" upper="6.2832" velocity="1.7453"/>
  </joint>
  <joint name="joint_2" type="revolute">
    <parent link="link_1"/>
    <child link="link_2"/>
    <origin rpy="0     -1.5708     -1.5708" xyz="0      0.2351           0"/>
    <axis xyz="0 0 1"/>
    <limit effort="841" lower="-2.1817" upper="2.1817" velocity="1.3963"/>
  </joint>
  <joint name="joint_3" type="revolute">
    <parent link="link_2"/>
    <child link="link_3"/>
    <origin rpy="0           0      1.5708" xyz="1.01           0           0"/>
    <axis xyz="0 0 1"/>
    <limit effort="484" lower="-2.7925" upper="2.7925" velocity="1.3963"/>
  </joint>
  <!-- Dummy joint_4 -->
  <joint name="joint_4" type="fixed">
    <parent link="link_3"/>
    <child link="link_4"/>
    <origin rpy="1.5708           0           0" xyz="0       -0.89           -0.1731"/>
    <axis xyz="0 0 1"/>
    <!-- <limit effort="163" lower="0" upper="0" velocity="0"/> -->
  </joint>
  <joint name="joint_5" type="revolute">
    <parent link="link_4"/>
    <child link="link_5"/>
    <origin rpy="-1.5708           0           0" xyz="0  0.1459  0"/>
    <axis xyz="0 0 1"/>
    <limit effort="70" lower="-6.2832" upper="6.2832" velocity="3.4907"/>
  </joint>
  <joint name="joint_6" type="revolute">
    <parent link="link_5"/>
    <child link="link_6"/>
    <origin rpy="1.5708           0           0" xyz="0       -0.13           0"/>
    <axis xyz="0 0 1"/>
    <limit effort="50" lower="-6.2832" upper="6.2832" velocity="6.2832"/>
  </joint>
  <!-- Transmission 1 -->
  <transmission name="tran1">
    <type>transmission_interface/SimpleTransmission</type>
    <joint name="joint1">
      <hardwareInterface>hardware_interface/PositionJointInterface</hardwareInterface>
    </joint>
    <actuator name="motor1">
      <hardwareInterface>hardware_interface/PositionJointInterface</hardwareInterface>
      <mechanicalReduction>1</mechanicalReduction>
    </actuator>
  </transmission>
  <!-- Transmission 2 -->
  <transmission name="tran2">
    <type>transmission_interface/SimpleTransmission</type>
    <joint name="joint2">
      <hardwareInterface>hardware_interface/PositionJointInterface</hardwareInterface>
    </joint>
    <actuator name="motor2">
      <hardwareInterface>hardware_interface/PositionJointInterface</hardwareInterface>
      <mechanicalReduction>1</mechanicalReduction>
    </actuator>
  </transmission>
  <!-- Transmission 3 -->
  <transmission name="tran3">
    <type>transmission_interface/SimpleTransmission</type>
    <joint name="joint3">
      <hardwareInterface>hardware_interface/PositionJointInterface</hardwareInterface>
    </joint>
    <actuator name="motor3">
      <hardwareInterface>hardware_interface/PositionJointInterface</hardwareInterface>
      <mechanicalReduction>1</mechanicalReduction>
    </actuator>
  </transmission>
  <!-- Transmission 4 -->
  <transmission name="tran4">
    <type>transmission_interface/SimpleTransmission</type>
    <joint name="joint4">
      <hardwareInterface>hardware_interface/PositionJointInterface</hardwareInterface>
    </joint>
    <actuator name="motor4">
      <hardwareInterface>hardware_interface/PositionJointInterface</hardwareInterface>
      <mechanicalReduction>1</mechanicalReduction>
    </actuator>
  </transmission>
  <!-- Transmission 5 -->
  <transmission name="tran5">
    <type>transmission_interface/SimpleTransmission</type>
    <joint name="joint5">
      <hardwareInterface>hardware_interface/PositionJointInterface</hardwareInterface>
    </joint>
    <actuator name="motor5">
      <hardwareInterface>hardware_interface/PositionJointInterface</hardwareInterface>
      <mechanicalReduction>1</mechanicalReduction>
    </actuator>
  </transmission>
  <!-- Transmission 6 -->
  <transmission name="tran6">
    <type>transmission_interface/SimpleTransmission</type>
    <joint name="joint6">
      <hardwareInterface>hardware_interface/PositionJointInterface</hardwareInterface>
    </joint>
    <actuator name="motor6">
      <hardwareInterface>hardware_interface/PositionJointInterface</hardwareInterface>
      <mechanicalReduction>1</mechanicalReduction>
    </actuator>
  </transmission>
  <!-- ros_control plugin -->
  <gazebo>
    <plugin filename="ign_ros2_control-system" name="ign_ros2_control::IgnitionROS2ControlPlugin">
      <ros>
        <namespace></namespace>
      </ros>
      <parameters>/home/theochoi/ros2_ws/install/dsr_controller2/share/dsr_controller2/config/dsr_controller2_gz_p3020.yaml</parameters>
    </plugin>
  </gazebo>
  <!-- Base -->
  <gazebo reference="base_0">
    <kp>100000.0</kp>
    <kd>100.0</kd>
    <mu1>30.0</mu1>
    <mu2>30.0</mu2>
    <maxVel>1.0</maxVel>
    <minDepth>0.001</minDepth>
  </gazebo>
  <!-- Link1 -->
  <gazebo reference="link1">
    <kp>100000.0</kp>
    <kd>100.0</kd>
    <mu1>30.0</mu1>
    <mu2>30.0</mu2>
    <maxVel>1.0</maxVel>
    <minDepth>0.001</minDepth>
  </gazebo>
  <!-- Link2 -->
  <gazebo reference="link2">
    <kp>100000.0</kp>
    <kd>100.0</kd>
    <mu1>30.0</mu1>
    <mu2>30.0</mu2>
    <maxVel>1.0</maxVel>
    <minDepth>0.001</minDepth>
  </gazebo>
  <!-- Link3 -->
  <gazebo reference="link3">
    <kp>100000.0</kp>
    <kd>100.0</kd>
    <mu1>30.0</mu1>
    <mu2>30.0</mu2>
    <maxVel>1.0</maxVel>
    <minDepth>0.001</minDepth>
  </gazebo>
  <!-- Link4 -->
  <gazebo reference="link4">
    <kp>100000.0</kp>
    <kd>100.0</kd>
    <mu1>30.0</mu1>
    <mu2>30.0</mu2>
    <maxVel>1.0</maxVel>
    <minDepth>0.001</minDepth>
  </gazebo>
  <!-- Link5 -->
  <gazebo reference="link5">
    <kp>100000.0</kp>
    <kd>100.0</kd>
    <mu1>30.0</mu1>
    <mu2>30.0</mu2>
    <maxVel>1.0</maxVel>
    <minDepth>0.001</minDepth>
  </gazebo>
  <!-- Link6 -->
  <gazebo reference="link6">
    <kp>100000.0</kp>
    <kd>100.0</kd>
    <mu1>30.0</mu1>
    <mu2>30.0</mu2>
    <maxVel>1.0</maxVel>
    <minDepth>0.001</minDepth>
  </gazebo>
  <!-- World fixed joint-->
  <link name="world"/>
  <joint name="world_fixed" type="fixed">
    <origin rpy="0 0 0" xyz="0 0 0"/>
    <parent link="world"/>
    <child link="base_link"/>
  </joint>
  <ros2_control name="p3020" type="system">
    <hardware>
      <plugin>dsr_hardware2/DRHWInterface</plugin>
      <param name="host"></param>
      <param name="rt_host"></param>
      <param name="port"></param>
      <param name="mode"></param>
      <param name="model"></param>
    </hardware>
    <joint name="joint_1">
      <command_interface name="position">
        <param name="min">{-2*pi}</param>
        <param name="max">{2*pi}</param>
      </command_interface>
      <command_interface name="velocity">
        <param name="min">-3.15</param>
        <param name="max">3.15</param>
      </command_interface>
      <state_interface name="position">
        <param name="initial_value">0.0</param>
      </state_interface>
      <state_interface name="velocity"/>
    </joint>
    <joint name="joint_2">
      <command_interface name="position">
        <param name="min">{-2*pi}</param>
        <param name="max">{2*pi}</param>
      </command_interface>
      <command_interface name="velocity">
        <param name="min">-3.15</param>
        <param name="max">3.15</param>
      </command_interface>
      <state_interface name="position">
        <param name="initial_value">0.0</param>
      </state_interface>
      <state_interface name="velocity"/>
    </joint>
    <joint name="joint_3">
      <command_interface name="position">
        <param name="min">{-pi}</param>
        <param name="max">{pi}</param>
      </command_interface>
      <command_interface name="velocity">
        <param name="min">-3.15</param>
        <param name="max">3.15</param>
      </command_interface>
      <state_interface name="position">
        <param name="initial_value">0.0</param>
      </state_interface>
      <state_interface name="velocity"/>
    </joint>
    <joint name="joint_4">
      <command_interface name="position">
        <param name="min">0.0</param>
        <param name="max">0.0</param>
      </command_interface>
      <command_interface name="velocity">
        <param name="min">0.0</param>
        <param name="max">0.0</param>
      </command_interface>
      <state_interface name="position">
        <param name="initial_value">0.0</param>
      </state_interface>
      <state_interface name="velocity"/>
    </joint>
    <joint name="joint_5">
      <command_interface name="position">
        <param name="min">{-2*pi}</param>
        <param name="max">{2*pi}</param>
      </command_interface>
      <command_interface name="velocity">
        <param name="min">-3.2</param>
        <param name="max">3.2</param>
      </command_interface>
      <state_interface name="position">
        <param name="initial_value">0.0</param>
      </state_interface>
      <state_interface name="velocity"/>
    </joint>
    <joint name="joint_6">
      <command_interface name="position">
        <param name="min">{-2*pi}</param>
        <param name="max">{2*pi}</param>
      </command_interface>
      <command_interface name="velocity">
        <param name="min">-3.2</param>
        <param name="max">3.2</param>
      </command_interface>
      <state_interface name="position">
        <param name="initial_value">0.0</param>
      </state_interface>
      <state_interface name="velocity"/>
    </joint>
  </ros2_control>
</robot>
